Internal Server Error: /api/signup/
Traceback (most recent call last):
  File "/home/isaac/ReportIt/ReportIt-Mobile/backend/.venv/lib/python3.13/site-packages/django/core/handlers/exception.py", line 55, in inner
    response = get_response(request)
  File "/home/isaac/ReportIt/ReportIt-Mobile/backend/.venv/lib/python3.13/site-packages/django/core/handlers/base.py", line 197, in _get_response
    response = wrapped_callback(request, *callback_args, **callback_kwargs)
  File "/home/isaac/ReportIt/ReportIt-Mobile/backend/.venv/lib/python3.13/site-packages/django/views/decorators/csrf.py", line 65, in _view_wrapper
    return view_func(request, *args, **kwargs)
  File "/home/isaac/ReportIt/ReportIt-Mobile/backend/.venv/lib/python3.13/site-packages/django/views/generic/base.py", line 105, in view
    return self.dispatch(request, *args, **kwargs)
           ~~~~~~~~~~~~~^^^^^^^^^^^^^^^^^^^^^^^^^^
  File "/home/isaac/ReportIt/ReportIt-Mobile/backend/.venv/lib/python3.13/site-packages/rest_framework/views.py", line 515, in dispatch
    response = self.handle_exception(exc)
  File "/home/isaac/ReportIt/ReportIt-Mobile/backend/.venv/lib/python3.13/site-packages/rest_framework/views.py", line 475, in handle_exception
    self.raise_uncaught_exception(exc)
    ~~~~~~~~~~~~~~~~~~~~~~~~~~~~~^^^^^
  File "/home/isaac/ReportIt/ReportIt-Mobile/backend/.venv/lib/python3.13/site-packages/rest_framework/views.py", line 486, in raise_uncaught_exception
    raise exc
  File "/home/isaac/ReportIt/ReportIt-Mobile/backend/.venv/lib/python3.13/site-packages/rest_framework/views.py", line 503, in dispatch
    self.initial(request, *args, **kwargs)
    ~~~~~~~~~~~~^^^^^^^^^^^^^^^^^^^^^^^^^^
  File "/home/isaac/ReportIt/ReportIt-Mobile/backend/.venv/lib/python3.13/site-packages/rest_framework/views.py", line 420, in initial
    self.perform_authentication(request)
    ~~~~~~~~~~~~~~~~~~~~~~~~~~~^^^^^^^^^
  File "/home/isaac/ReportIt/ReportIt-Mobile/backend/.venv/lib/python3.13/site-packages/rest_framework/views.py", line 330, in perform_authentication
    request.user
  File "/home/isaac/ReportIt/ReportIt-Mobile/backend/.venv/lib/python3.13/site-packages/rest_framework/request.py", line 232, in user
    self._authenticate()
    ~~~~~~~~~~~~~~~~~~^^
  File "/home/isaac/ReportIt/ReportIt-Mobile/backend/.venv/lib/python3.13/site-packages/rest_framework/request.py", line 395, in _authenticate
    self._not_authenticated()
    ~~~~~~~~~~~~~~~~~~~~~~~^^
  File "/home/isaac/ReportIt/ReportIt-Mobile/backend/.venv/lib/python3.13/site-packages/rest_framework/request.py", line 405, in _not_authenticated
    if api_settings.UNAUTHENTICATED_USER:
       ^^^^^^^^^^^^^^^^^^^^^^^^^^^^^^^^^
  File "/home/isaac/ReportIt/ReportIt-Mobile/backend/.venv/lib/python3.13/site-packages/rest_framework/settings.py", line 227, in __getattr__
    val = perform_import(val, attr)
  File "/home/isaac/ReportIt/ReportIt-Mobile/backend/.venv/lib/python3.13/site-packages/rest_framework/settings.py", line 168, in perform_import
    return import_from_string(val, setting_name)
  File "/home/isaac/ReportIt/ReportIt-Mobile/backend/.venv/lib/python3.13/site-packages/rest_framework/settings.py", line 179, in import_from_string
    return import_string(val)
  File "/home/isaac/ReportIt/ReportIt-Mobile/backend/.venv/lib/python3.13/site-packages/django/utils/module_loading.py", line 30, in import_string
    return cached_import(module_path, class_name)
  File "/home/isaac/ReportIt/ReportIt-Mobile/backend/.venv/lib/python3.13/site-packages/django/utils/module_loading.py", line 15, in cached_import
    module = import_module(module_path)
  File "/usr/lib/python3.13/importlib/__init__.py", line 88, in import_module
    return _bootstrap._gcd_import(name[level:], package, level)
           ~~~~~~~~~~~~~~~~~~~~~~^^^^^^^^^^^^^^^^^^^^^^^^^^^^^^
  File "<frozen importlib._bootstrap>", line 1387, in _gcd_import
  File "<frozen importlib._bootstrap>", line 1360, in _find_and_load
  File "<frozen importlib._bootstrap>", line 1331, in _find_and_load_unlocked
  File "<frozen importlib._bootstrap>", line 935, in _load_unlocked
  File "<frozen importlib._bootstrap_external>", line 1026, in exec_module
  File "<frozen importlib._bootstrap>", line 488, in _call_with_frames_removed
  File "/home/isaac/ReportIt/ReportIt-Mobile/backend/.venv/lib/python3.13/site-packages/django/contrib/auth/models.py", line 39, in <module>
    class Permission(models.Model):
    ...<45 lines>...
        natural_key.dependencies = ["contenttypes.contenttype"]
  File "/home/isaac/ReportIt/ReportIt-Mobile/backend/.venv/lib/python3.13/site-packages/django/db/models/base.py", line 136, in __new__
    raise RuntimeError(
    ...<3 lines>...
    )
RuntimeError: Model class django.contrib.auth.models.Permission doesn't declare an explicit app_label and isn't in an application in INSTALLED_APPS.
"POST /api/signup/ HTTP/1.1" 500 179715
